Workbook

Sheet Results
A1: Authors | B1: Author full names | C1: Author(s) ID | D1: Title | E1: Year | F1: Source title | G1: Volume | H1: Issue | I1: Art. No. | J1: Page start | K1: Page end | L1: Cited by | M1: DOI | N1: Link | O1: Abstract | P1: Author Keywords | Q1: Index Keywords | R1: Document Type | S1: Publication Stage | T1: Open Access | U1: Source | V1: EID
A2: Ton K. | B2: Ton, Karen (57213145412) | C2: 57213145412 | D2: Do Shared Auditors Improve Audit Quality? Evidence from Banking Relationships | E2: 2023 | F2: Accounting Review | G2: 98 | H2: 1 | J2: 423 | K2: 451 | L2: 17 | M2: 10.2308/TAR-2017-0179 | N2: https://www.scopus.com/inward/record.uri?eid=2-s2.0-85168957043&doi=10.2308%2FTAR-2017-0179&partnerID=40&md5=35ea053474f56ceb694d5a8a7755d047 | O2: Auditor knowledge is a key element in explaining the supply of audit quality, yet understanding of the drivers of this knowledge in the archival literature is limited. This study uses an archival approach to examine whether the sharing of auditors among firms in banking relationships results in information transfers that improve audit quality. I find that audit quality improves for both borrowers and lenders who share the same auditor office. Specifically, lenders who share an auditor office with their borrowers have more accurate loan-loss provisions, especially lenders with smaller commercial loan portfolios. Borrowers who share an auditor office with their lender are less likely to receive a clean audit opinion just prior to bankruptcy. Overall, these findings are consistent with shared auditors in banking relationships developing client specific knowledge that is transferable across clients and industries. © 2023 American Accounting Association. All rights reserved. | P2: audit quality; banking relationship; information transfer; shared auditors | R2: Article | S2: Final | U2: Scopus | V2: 2-s2.0-85168957043
A3: Tan H.-T.; Yeo F. | B3: Tan, Hun-Tong (7403011560); Yeo, Feng (57211460987) | C3: 7403011560; 57211460987 | D3: What Happens When Managers Are Informed? Effects of Critical Audit Matter Awareness and Auditor Relationship on Managers’ Accounting Estimates | E3: 2022 | F3: Accounting Review | G3: 97 | H3: 4 | J3: 399 | K3: 416 | L3: 20 | M3: 10.2308/TAR-2019-0370 | N3: https://www.scopus.com/inward/record.uri?eid=2-s2.0-85161047737&doi=10.2308%2FTAR-2019-0370&partnerID=40&md5=0d5b91735f149d78a73f6b9c9f8bcd50 | O3: We examine how managers’ accounting estimates are affected by whether they are informed about an impending critical audit matter (CAM) disclosure from a close or distant auditor. A close (distant) auditor is one who has a smaller (greater) social distance from the client in terms of their working relationship. We predict and find that being informed about an impending CAM by a close (distant) auditor leads to more (less) aggressive estimates than if managers are not informed. With a close auditor-client relationship, managers perceive a CAM disclosure as forewarning investors about estimate subjectivity, thus providing a moral license to report more aggressively. With a distant relationship, a CAM disclosure does not provide a moral license, but signals greater auditor scrutiny, which leads to less aggressive reporting. Our results inform regulators and standard setters about the effects of CAM on managers’ reporting decisions in the presence of a close auditor-client relationship. © 2022 American Accounting Association. All rights reserved. | P3: aggressive reporting; auditor-client working relationship; impending critical audit matters; moral licensing | R3: Article | S3: Final | U3: Scopus | V3: 2-s2.0-85161047737
A4: Lyle M.R.; Yohn T.L. | B4: Lyle, Matthew R. (26646633200); Yohn, Teri Lombardi (6508176752) | C4: 26646633200; 6508176752 | D4: Fundamental Analysis and Mean-Variance Optimal Portfolios | E4: 2022 | F4: Accounting Review | G4: 96 | H4: 6 | J4: 303 | K4: 327 | L4: 11 | M4: 10.2308/TAR-2019-0622 | N4: https://www.scopus.com/inward/record.uri?eid=2-s2.0-85132667755&doi=10.2308%2FTAR-2019-0622&partnerID=40&md5=0f6d7246db68c79a72ac488bf3a3a8e0 | O4: We integrate fundamental analysis with mean-variance portfolio optimization to form fully optimized fundamental portfolios. We find that fully optimized fundamental portfolios produce large out-of-sample factor alphas with high Sharpe ratios. They substantially outperform equal-weighted and value-weighted portfolios of stocks in the extreme decile of expected returns, an approach commonly used in fundamental analysis research. They also outperform the factor-based and parametric portfolio policy approaches used in the prior portfolio optimization literature. The relative performance gains from mean-variance optimized fundamental portfolios are persistent through time, robust to eliminating small capitalization firms from the investment set, and robust to incorporating estimated transactions costs. Our results suggest that future fundamental analysis research could implement this portfolio optimization approach to provide greater investment insights. © 2022 American Accounting Association. All rights reserved. | P4: fundamental analysis; fundamentals-based expected returns; modeling; portfolio optimization; valuation | R4: Article | S4: Final | U4: Scopus | V4: 2-s2.0-85132667755
A5: Gallemore J.; Jacob M. | B5: Gallemore, John (56194898700); Jacob, Martin (37028466200) | C5: 56194898700; 37028466200 | D5: Corporate Tax Enforcement and Business Activity | E5: 2025 | F5: Accounting Review | G5: 100 | H5: 1 | J5: 231 | K5: 260 | L5: 9 | M5: 10.2308/TAR-2023-0011 | N5: https://www.scopus.com/inward/record.uri?eid=2-s2.0-85215000470&doi=10.2308%2FTAR-2023-0011&partnerID=40&md5=6eb2bd63531c6a09ba03fa469584d277 | O5: We examine the consequences of corporate tax enforcement for business activity. Using two different empirical approaches—a regional design and a firm-level design—we document that corporate tax enforcement is negatively associated with business activity, as measured by establishments and employment. This association is economically significant and is robust to tests that mitigate concerns regarding endogeneity and measurement. Furthermore, we find that the negative association between tax enforcement and business activity varies substantially in the cross-section. Specifically, we find that it is weaker for regions and firms with greater access to external financing sources and is stronger for regions and firms where compliance costs are likely higher and for which the ex ante costs of tax enforcement are greater. Our findings suggest that the effects of tax enforcement on business activity are economically important and heterogeneous, which should be of interest to academics and policymakers. © 2025 American Accounting Association. All rights reserved. | P5: business activity; compliance costs; corporate tax enforcement; employment; local economies | R5: Article | S5: Final | T5: All Open Access; Bronze Open Access | U5: Scopus | V5: 2-s2.0-85215000470
A6: Glaeser S.; Schonberger B.; Wasley C.E.; Xiao J.J. | B6: Glaeser, Stephen (57195741898); Schonberger, Bryce (57213197271); Wasley, Charles E. (6507362682); Xiao, Jason J. (57225928882) | C6: 57195741898; 57213197271; 6507362682; 57225928882 | D6: Private Information Acquisition via Freedom of Information Act Requests Made to the Securities and Exchange Commission | E6: 2023 | F6: Accounting Review | G6: 98 | H6: 3 | J6: 229 | K6: 255 | L6: 7 | M6: 10.2308/TAR-2021-0146 | N6: https://www.scopus.com/inward/record.uri?eid=2-s2.0-85162804594&doi=10.2308%2FTAR-2021-0146&partnerID=40&md5=df8e900bae32f7ec7062a0a525f40dde | O6: There is limited evidence about when, why, and which individuals incur costs to acquire nonpublic information about a firm, largely due to the difficulty of observing private information acquisition. To overcome this difficulty, we obtain data on Freedom of Information Act (FOIA) requests submitted to the Securities and Exchange Commission (SEC). We predict and find that perceived information asymmetry between managers and outsiders resulting from both proprietary and agency costs triggers FOIA search. We categorize organizations making FOIA requests using their business descriptions and find that many, including law and intellectual property firms, are not expressly interested in obtaining information for near-term equity trading. Instead, their search activity relates to determinants beyond financial characteristics, including patent litigation and executive turnover. Taken together, we provide evidence on private information search by a relatively unexamined set of organizations and shed new light on the function of the SEC’s Office of FOIA Services. © 2023 American Accounting Association. All rights reserved. | P6: agency costs; competition; disclosure; Freedom of Information Act; information acquisition; information search; lawsuits; proprietary costs | R6: Article | S6: Final | U6: Scopus | V6: 2-s2.0-85162804594
A7: Tegeler A.C.; Brown V.L.; Downey D.H. | B7: Tegeler, Amy C. (57201384840); Brown, Veena L. (56599909300); Downey, Denise Hanes (57202337345) | C7: 57201384840; 56599909300; 57202337345 | D7: Auditor Perceptions, Reactions, and Responses to PCAOB Inspection Feedback | E7: 2025 | F7: Accounting Review | G7: 100 | H7: 1 | J7: 437 | K7: 464 | L7: 1 | M7: 10.2308/TAR-2023-0021 | N7: https://www.scopus.com/inward/record.uri?eid=2-s2.0-85214571410&doi=10.2308%2FTAR-2023-0021&partnerID=40&md5=84933b1a7cfe8803bf9d6f20701ef102 | O7: Guided by the performance feedback literature, we study PCAOB inspections as a nonstandard feedback event. We use an experiential questionnaire to collect and analyze perceptions, reactions, and responses to inspection feedback from 120 partners and managers subject to a recent PCAOB inspection. Despite varying perceptions, we find on average auditors perceive strong firm support but also that firms acquiesce to inspectors. Generally, the feedback source, inspectors, are perceived as professional, organized, and knowledgeable and auditors agree with the feedback message, perceiving it as consistent and well reasoned. We observe a range of auditor reactions (satisfaction with and motivated to use inspection feedback), responses at the engagement level (improvements to audit quality and inspection risk or impression management), and individual responses. Multivariate analyses show more positive feedback perceptions improve reactions, which enhance desirability of responses and are robust to considering the inspection outcome, offering insights for refining inspection interactions and processes. © 2025 American Accounting Association. All rights reserved. | P7: audit inspections; audit quality; experiential questionnaire; feedback; inspection impression management; PCAOB | R7: Article | S7: Final | U7: Scopus | V7: 2-s2.0-85214571410
A8: Gunn J.L.; Li C.; Liao L.; Zhou S. | B8: Gunn, Joshua L. (57198420906); Li, Chan (24071088600); Liao, Lin (56045006800); Zhou, Shan (55648845500) | C8: 57198420906; 24071088600; 56045006800; 55648845500 | D8: Is It Better to Kill Two Birds with One Stone? Internal Control Audit Quality and Audit Costs for Integrated versus Nonintegrated Audits | E8: 2023 | F8: Accounting Review | G8: 98 | H8: 1 | J8: 251 | K8: 283 | L8: 23 | M8: 10.2308/TAR-2019-0220 | N8: https://www.scopus.com/inward/record.uri?eid=2-s2.0-85161800226&doi=10.2308%2FTAR-2019-0220&partnerID=40&md5=599c342351a22ec08e3f8194bdc8690f | O8: Audits of internal control over financial reporting (ICFR) are typically “integrated” with the audit of the financial statements (FSs)—both audits are conducted by the same audit firm, which designs procedures to satisfy the objectives of both audits simultaneously. A common assumption is that integrating the two audits is more effective and efficient than performing them separately. However, this assumption has not been tested empirically. Using a sample of Chinese companies that employ different audit firms for their FS and ICFR audits (i.e., nonintegrated auditors), we find evidence that challenges this assumption. Specifically, we find ICFR audit quality is higher for nonintegrated audits compared to integrated audits. Moreover, total audit fees are lower for nonintegrated audits, despite higher ICFR audit fees. © 2023 American Accounting Association. All rights reserved. | P8: audit cost; audit quality; integrated audit; internal control over financial reporting; SOX | R8: Article | S8: Final | U8: Scopus | V8: 2-s2.0-85161800226
A9: Hayes R.M.; Tian X.; Wang X. | B9: Hayes, Rachel M. (7402082490); Tian, Xiaoli (58345641900); Wang, Xue (56477533700) | C9: 7402082490; 58345641900; 56477533700 | D9: Deregulation and Board Policies: Evidence from Performance and Risk Exposure Measures Used in Bank CEO Turnover Decisions | E9: 2023 | F9: Accounting Review | G9: 98 | H9: 3 | J9: 257 | K9: 283 | L9: 4 | M9: 10.2308/TAR-2018-0752 | N9: https://www.scopus.com/inward/record.uri?eid=2-s2.0-85162751978&doi=10.2308%2FTAR-2018-0752&partnerID=40&md5=65fcbde1b8f3041cc76e1b3e2f07f4d5 | O9: We examine the effects of banking deregulation on bank board policies—specifically, whether deregulation affects the performance and risk exposure measures used in bank CEO turnover decisions. Using the staggered adoption of interstate branching as our setting, we find that bank CEO turnover is more (less) sensitive to stock (accounting) performance after deregulation. We also find that deregulation is associated with a higher sensitivity of bank CEO turnover to the idiosyncratic component of tail risk. Moreover, such changes in turnover policies primarily exist in large banks and federally chartered banks, which are best positioned to exploit growth opportunities, and in banks that expand branch operations after deregulation. Our results indicate an increased emphasis on stock performance and tail risk in turnover decisions when growth opportunities are greater in the deregulated environment. The findings provide evidence that the information used in board decisions varies with features of the competitive environment. © 2023 American Accounting Association. All rights reserved. | P9: CEO turnover; deregulation; growth | R9: Article | S9: Final | U9: Scopus | V9: 2-s2.0-85162751978
A10: Griffin P.A.; Hong H.A.; Ryou J.W. | B10: Griffin, Paul A. (36015132500); Hong, Hyun A. (55894289400); Ryou, Ji Woo (57202872742) | C10: 36015132500; 55894289400; 57202872742 | D10: Proprietary Costs: Why Do R&D-Active Firms Choose Single-Lender Financing? | E10: 2022 | F10: Accounting Review | G10: 97 | H10: 6 | J10: 263 | K10: 296 | L10: 15 | M10: 10.2308/TAR-2018-0158 | N10: https://www.scopus.com/inward/record.uri?eid=2-s2.0-85138736055&doi=10.2308%2FTAR-2018-0158&partnerID=40&md5=c1a8b8a3c4506acb76d740eb6a92e4d9 | O10: We examine whether proprietary costs drive R&D-active firms’ choice of private loan structure. We find that R&D-active firms are more likely to choose single-lender over multi-lender private loan financing. This is consistent with the theory that high-ability entrepreneurs protect their proprietary knowledge by communicating it to a single lender while disclosing generic and less sensitive information to the public. This propensity, however, significantly decreases after the enactment of the American Inventor’s Protection Act (AIPA), which accelerated public disclosure of firms’ patent details in filings with the U.S. Patent and Trademark Office. This accelerated public disclosure potentially caused R&D information to spill over to rivals, increasing the proprietary costs of single-lender borrowers. AIPA enactment also increased the spread on R&D-active firms’ single-lender loans. These findings contribute to the voluntary disclosure and financing choice literature by linking R&D-active firms’ choice of single-lender financing to the proprietary costs of public disclosure. © 2022 American Accounting Association. All rights reserved. | P10: American Inventor’s Protection Act; financing innovation; proprietary costs; R&D-active firms; single-lender financing | R10: Article | S10: Final | U10: Scopus | V10: 2-s2.0-85138736055
A11: Loudis J.A. | B11: Loudis, Johnathan A. (16643179100) | C11: 16643179100 | D11: Stock Price Reactions to the Information and Bias in Analyst-Expected Returns | E11: 2024 | F11: Accounting Review | G11: 99 | H11: 4 | J11: 281 | K11: 313 | L11: 0 | M11: 10.2308/TAR-2022-0309 | N11: https://www.scopus.com/inward/record.uri?eid=2-s2.0-85197728221&doi=10.2308%2FTAR-2022-0309&partnerID=40&md5=b07d472c1c3ca1a97ed8724883e53ff5 | O11: I use a novel decomposition to estimate information and bias components from the returns implied by analyst price targets and provide evidence that prices simultaneously under-react to information and over-react to bias. Price reactions to information are permanent, and prices drift in the direction of their initial reaction for up to 12 months. Price reactions to bias are transitory, and prices reverse their initial reaction after about three months. Price reactions are relatively efficient. Approximately 85 percent of the total price reaction to information occurs during price target announcement months. Market participants are able to mostly (but not fully) debias analyst-expected returns before incorporating them into prices, with the announcement-month reaction to bias being relatively weak at about 15 percent of its reaction to information. A trading strategy analysis implies that mispricing induced by bias is only about one-third of that implied by prior research. © 2024 American Accounting Association. All rights reserved. | P11: analysts; cross-section; expected returns; market efficiency; price drift; price targets; return reversal | R11: Article | S11: Final | T11: All Open Access; Bronze Open Access | U11: Scopus | V11: 2-s2.0-85197728221
A12: Bentley J.W.; Lambert T.A.; Wang E. | B12: Bentley, Jeremiah W. (57189918952); Lambert, Tamara A. (53664036100); Wang, Elaine (55558004700) | C12: 57189918952; 53664036100; 55558004700 | D12: The Effect of Increased Audit Disclosure on Managers’ Real Operating Decisions: Evidence from Disclosing Critical Audit Matters | E12: 2021 | F12: Accounting Review | G12: 96 | H12: 1 | J12: 23 | K12: 40 | L12: 62 | M12: 10.2308/TAR-2017-0486 | N12: https://www.scopus.com/inward/record.uri?eid=2-s2.0-85101257543&doi=10.2308%2FTAR-2017-0486&partnerID=40&md5=c83885c8436a1f61fd2a29c123868233 | O12: We investigate whether and how a ‘‘critical audit matter’’ (CAM) disclosure affects managers’ real operating decisions in two contexts (issuing a loan that decreases versus increases the average risk profile of loan portfolios, or choosing to hedge versus speculate on commodity risk). We expect that a CAM disclosure increases disclosure costs and implies expanded auditor support for both types of activities, but we expect implied auditor support to be valued more highly for risk-increasing than for risk-decreasing activities. As a result, we predict that a CAM disclosure decreases managers’ risk-decreasing activities (due to increased disclosure costs) more than managers’ risk-increasing activities (as the implied auditor support counteracts the increased disclosure costs). We find evidence consistent with our prediction across multiple experiments. Our study sheds light on the unintended consequences of a CAM disclosure and provides insight to relevant parties as the new standard goes into effect. © 2021 American Accounting Association. All rights reserved. | P12: Auditor reporting model; Critical audit matters (CAMs); Disclosure efficiency; Managers’ real operating decisions; Operating distortion | R12: Article | S12: Final | U12: Scopus | V12: 2-s2.0-85101257543
A13: Ashraf M.; Sunder J. | B13: Ashraf, Musaib (57219866977); Sunder, Jayanthi (16240040800) | C13: 57219866977; 16240040800 | D13: Can Shareholders Benefit from Consumer Protection Disclosure Mandates? Evidence from Data Breach Disclosure Laws | E13: 2023 | F13: Accounting Review | G13: 98 | H13: 4 | J13: 1 | K13: 32 | L13: 34 | M13: 10.2308/TAR-2020-0787 | N13: https://www.scopus.com/inward/record.uri?eid=2-s2.0-85146311296&doi=10.2308%2FTAR-2020-0787&partnerID=40&md5=745a055e0cc6244dab8d6ed7afbcef01 | O13: Data breach disclosure laws are state-level disclosure mandates intended to protect individuals from the consequences of identity theft. However, we argue that the laws help reduce shareholder risk by encouraging managers to take real actions to reduce firms' exposure to cyber risk. Consistent with this argument, we find an onaverage decrease in shareholder risk, proxied by cost of equity, after the staggered passage of these laws. We also find the effect is attenuated for firms that already took real actions to manage cyber risk before the laws. Further, after these laws, firms are more likely to increase cybersecurity investments and have a cybersecurity officer. Finally, we observe positive abnormal returns on key dates related to the passage of these laws. Our collective evidence suggests that consumer protection disclosure mandates can benefit shareholders and, specifically, that regulators can use disclosure mandates to incentivize managers to reduce firms' exposure to cyber risk. © 2023 American Accounting Association. All rights reserved. | P13: capital markets; consumer protection; corporate governance; cost of capital; cyber risk; cybersecurity; disclosure; disclosure mandates; information technology; real effects | R13: Article | S13: Final | U13: Scopus | V13: 2-s2.0-85146311296
A14: Burke J.J.; Hoitash R.; Hoitash U.; Xiao S. | B14: Burke, Jenna J. (57141536900); Hoitash, Rani (20433597800); Hoitash, Udi (24337937400); Xiao, Summer (57222093671) | C14: 57141536900; 20433597800; 24337937400; 57222093671 | D14: The Disclosure and Consequences of U.S. Critical Audit Matters | E14: 2023 | F14: Accounting Review | G14: 98 | H14: 2 | J14: 59 | K14: 95 | L14: 104 | M14: 10.2308/TAR-2021-0013 | N14: https://www.scopus.com/inward/record.uri?eid=2-s2.0-85175458078&doi=10.2308%2FTAR-2021-0013&partnerID=40&md5=2997d71c36797ab53bd5f402e72607ef | O14: This study uses difference-in-differences (DiD) analyses to examine the consequences of adopting the U.S. critical audit matter (CAM) disclosure requirement for preparers and users of financial reports. The CAM requirement is one of the largest expansions of the U.S. audit report since the 1940s. We document significant changes to financial statement footnotes referenced by CAMs, which suggests an indirect consequence where management disclosure changes in areas that are expected to be scrutinized following auditor-provided disclosure. Results also suggest that, on average, CAM disclosures do not provide incremental information to the market. To further examine market reaction, we develop well-specified prediction models for the expected number and subject areas of CAMs. We find limited initial evidence that the market reacts negatively when unexpected CAMs are disclosed. Overall, our findings provide insights on the new CAM standard and particularly demonstrate its relevance to management disclosure decisions and to the market. © 2023 American Accounting Association. All rights reserved. | P14: audit fees; audit quality; critical audit matters; expanded audit report; footnote disclosure; market reaction; PCAOB; textual analysis; unexpected disclosures; XBRL | R14: Article | S14: Final | U14: Scopus | V14: 2-s2.0-85175458078
A15: Chen Y.; Ofosu E.; Pittman J. | B15: Chen, Yangyang (55224388500); Ofosu, Emmanuel (57455133200); Pittman, Jeffrey (7102551904) | C15: 55224388500; 57455133200; 7102551904 | D15: The Cost of Investor Protection: Bank Loan Contracting During SEC Investigations | E15: 2026 | F15: Accounting Review | G15: 101 | H15: 1 | J15: 203 | K15: 234 | L15: 1 | M15: 10.2308/TAR-2024-0405 | N15: https://www.scopus.com/inward/record.uri?eid=2-s2.0-105030514518&doi=10.2308%2FTAR-2024-0405&partnerID=40&md5=221a2e9d7110d36a2a48cf8da216226a | O15: In examining the loan contracting implications of SEC investigations, we document that banks charge higher loan spreads when borrowers are under investigation, with the rise in interest rates varying predictably with lender characteristics. Further, our evidence implies that the debt pricing impact of SEC investigations is amplified for borrowers suffering worse credit quality and information asymmetry as well as those relying more on bank loans. These findings suggest that banks perceive increased risk for borrowers under SEC scrutiny while also leveraging their knowledge of the investigations to extract rents. Supplemental analyses reveal tighter nonspread loan terms and a higher likelihood of amending existing loan contracts during SEC investigations. Additionally, the tightening of loan terms reverses for investigations that conclude without enforcement actions. Overall, our research identifies an economic cost of SEC investigations and alerts regulators to these costs when deciding whether to launch an investigation. © 2026, American Accounting Association. All rights reserved. | P15: bank loan contracting; lending risk; private information; rent extraction; SEC investigation | R15: Article | S15: Final | T15: All Open Access; Bronze Open Access | U15: Scopus | V15: 2-s2.0-105030514518
A16: Kim S.; Kim S.; Ryan S.G. | B16: Kim, Sehwa (57226112834); Kim, Seil (57213778876); Ryan, Stephen G. (35574572600) | C16: 57226112834; 57213778876; 35574572600 | D16: Banks’ Motivations for Designating Securities as Held to Maturity | E16: 2025 | F16: Accounting Review | G16: 100 | H16: 4 | J16: 303 | K16: 330 | L16: 1 | M16: 10.2308/TAR-2023-0615 | N16: https://www.scopus.com/inward/record.uri?eid=2-s2.0-105009652064&doi=10.2308%2FTAR-2023-0615&partnerID=40&md5=253d2a3043c41bd2edbb5cce029157cd | O16: We provide evidence that banks classify fixed-rate debt investment securities as held to maturity (HTM) rather than as available for sale (AFS) when HTM classification provides preferred financial accounting and regulatory capital treatments, not because they have a distinct economically motivated intent and ability to hold the securities to maturity. Specifically, we document predictably divergent security classifications by three categories of banks that differ in whether the regulatory accumulated other comprehensive income (AOCI) filter, which removes AOCI from Tier 1 capital, applies in four subperiods of our 2012–2022 sample period. The boundaries of the subperiods reflect changes in the AOCI filter’s applicability in 2014 and 2019 and the sharp rise in interest rates beginning in late 2021. We further find that the bank categories differ in the interest rate risk of their AFS securities and the extents to which they economically hedge that risk using derivatives and uninsured deposits. © 2025 American Accounting Association. All rights reserved. | P16: AOCI filter; banks; held to maturity; investment securities; regulatory capital | R16: Article | S16: Final | T16: All Open Access; Bronze Open Access | U16: Scopus | V16: 2-s2.0-105009652064
A17: Chen J.; Dou Y.; Zou Y. | B17: Chen, Jing (57016173800); Dou, Yiwei (56273698300); Zou, Youli (56706771300) | C17: 57016173800; 56273698300; 56706771300 | D17: Information externalities of sfas 161: Evidence from supply chains | E17: 2021 | F17: Accounting Review | G17: 96 | H17: 4 | J17: 179 | K17: 202 | L17: 17 | M17: 10.2308/TAR-2018-0578 | N17: https://www.scopus.com/inward/record.uri?eid=2-s2.0-85111536189&doi=10.2308%2FTAR-2018-0578&partnerID=40&md5=741a94afc9cfa7861d6d48c9101d56cc | O17: Effective in 2009, SFAS 161 requires enhanced disclosures about derivative use and hedging activities. We test for changes to the information environment of firms whose disclosure policy is unaffected by this standard directly. Using a sample of non-users of derivatives, we find an increase in stock liquidity after their critical customers expand derivative disclosures under SFAS 161. The effect persists for one year and becomes insignificant in subsequent years as the firms dial back their voluntary disclosure. The effect is also more salient for firms that have stronger economic links with their customers and for firms whose customers exhibit more significant improvements in derivative disclosures. The findings suggest that the mandatory derivative disclosures due to SFAS 161 lead to short-term positive information externalities along supply chains. © 2021 American Accounting Association. All rights reserved. | P17: Disclosure regulation; Hedge accounting; Information externalities; Market liquidity; SFAS 161; Supply chains | R17: Article | S17: Final | U17: Scopus | V17: 2-s2.0-85111536189
A18: Hawkins S.R.; Pickerd J.; Summers S.L.; Wood D.A. | B18: Hawkins, Steven R. (57209739649); Pickerd, Jeffrey (49663865200); Summers, Scott L. (7007176901); Wood, David A. (7404401863) | C18: 57209739649; 49663865200; 7007176901; 7404401863 | D18: The Development of the Process Mining Event Log Generator (PMELG) Tool | E18: 2023 | F18: Accounting Review | G18: 35 | H18: 3 | L18: 1 | M18: 10.2308/HORIZONS-2022-153 | N18: https://www.scopus.com/inward/record.uri?eid=2-s2.0-85173742967&doi=10.2308%2FHORIZONS-2022-153&partnerID=40&md5=77c043d60aaa89e48e943fe12c4f84a8 | O18: Process mining is an emerging technology that allows users to visualize all potential variations of business processes within an organization. It holds significant potential for impacting the field of accounting. However, training professionals and students in its use is challenging due to a lack of event data applicable to accounting and auditing scenarios. To address this issue, we developed an easy-to-use tool called the Process Mining Event Log Generator (PMELG) for generating process mining data files for the order-to-cash process. With the PMELG tool, users can create realistic datasets that incorporate key accounting and auditing concepts, such as segregation of duties issues, internal control violations, operational inefficiencies, and fraudulent behavior. We validate this tool with professionals and academics. Both groups believe the tool will be beneficial for both practitioners and academic audiences. © 2023 American Accounting Association. All rights reserved. | P18: data analytics; data generation; event logs; process mining | R18: Article | S18: Final | U18: Scopus | V18: 2-s2.0-85173742967
A19: Feng F.Z.; Wang W.; Wu Y.; Zhang G. | B19: Feng, Felix Zhiyu (57196058422); Wang, Wenyu (57201008264); Wu, Yufeng (59511581200); Zhang, Gaoqing (57190688749) | C19: 57196058422; 57201008264; 59511581200; 57190688749 | D19: Ignorance Is Bliss: The Screening Effect of (Noisy) Information | E19: 2025 | F19: Accounting Review | G19: 100 | H19: 1 | J19: 201 | K19: 230 | L19: 2 | M19: 10.2308/TAR-2023-0112 | N19: https://www.scopus.com/inward/record.uri?eid=2-s2.0-85214802925&doi=10.2308%2FTAR-2023-0112&partnerID=40&md5=2a927e3506f372de37108686701e1250 | O19: This paper studies the value of a firm’s internal information when the firm faces an adverse selection problem arising from unobservable managerial abilities. Although more precise information allows the firm to make ex post more efficient investment decisions, noisier information has an ex ante screening effect that allows the firm to attract on-average better managers. The tradeoff between more effective screening of managers and more informed investment implies a nonmonotonic relationship between firm value and information quality. A marginal improvement in information quality does not necessarily lead to an overall improvement in firm value. © 2025 American Accounting Association. All rights reserved. | P19: accounting noise; corporate governance; internal information; screening | R19: Article | S19: Final | U19: Scopus | V19: 2-s2.0-85214802925
A20: Kachelmeier S.J.; Webb R.A.; Williamson M.G. | B20: Kachelmeier, Steven J. (6506220075); Webb, R. Alan (57687898300); Williamson, Michael G. (23098716300) | C20: 6506220075; 57687898300; 23098716300 | D20: Do Performance-Contingent Incentives Help or Hinder Divergent Thinking? | E20: 2024 | F20: Accounting Review | G20: 99 | H20: 2 | J20: 229 | K20: 248 | L20: 1 | M20: 10.2308/TAR-2020-0751 | N20: https://www.scopus.com/inward/record.uri?eid=2-s2.0-85187711993&doi=10.2308%2FTAR-2020-0751&partnerID=40&md5=4bdf64bbcb3e7de246494f3a422f4b66 | O20: Toward the goal of reconciling conflicting arguments on whether performance-based incentives facilitate or impede divergent thinking, we identify a feature common to prior demonstrations of negative incentive effects: they generally involve tasks with only one correct solution. Our first experiment replicates a negative incentive effect when insight problems require “bottom-up” divergent thinking from an unexpected resource to the problem it is uniquely equipped to solve, whereas our second experiment finds a positive incentive effect in the more general case of problems that enable “top-down” divergent thinking from a problem to multiple potential solutions. We also observe a positive incentive effect in a third experiment that measures the time needed to generate a solution to problems that have multiple potential solutions and in a fourth experiment in which participants design insight problems. Overall, our findings suggest that any harmful effects of performance-based incentives are likely restricted to highly constrained settings. © 2024 American Accounting Association. All rights reserved. | P20: creativity; divergent thinking; incentives; insight problems; top-down versus bottom-up reasoning | R20: Article | S20: Final | U20: Scopus | V20: 2-s2.0-85187711993
A21: Beneish M.D.; Farber D.B.; Glendening M.; Shaw K.W. | B21: Beneish, Messod D. (6603303677); Farber, David B. (23491780200); Glendening, Matthew (57193741378); Shaw, Kenneth W. (7202206489) | C21: 6603303677; 23491780200; 57193741378; 7202206489 | D21: Aggregate Financial Misreporting and the Predictability of U.S. Recessions and GDP Growth | E21: 2023 | F21: Accounting Review | G21: 98 | H21: 5 | J21: 129 | K21: 159 | L21: 3 | M21: 10.2308/TAR-2021-0160 | N21: https://www.scopus.com/inward/record.uri?eid=2-s2.0-85162007700&doi=10.2308%2FTAR-2021-0160&partnerID=40&md5=860e9b6bb03e112ea769b8ea6434edda | O21: This study examines the incremental predictive power of aggregate measures of financial misreporting for recession and real gross domestic product (GDP) growth. We draw on prior research suggesting that misreporting has real economic effects because it represents misinformation on which firms base their investment, hiring, and production decisions. We find that aggregate M-Score incrementally predicts recessions at forecast horizons of five to eight quarters ahead. We also find that aggregate M-Score is significantly associated with lower future growth in real GDP, real investment, consumption, and industrial production. Additionally, our result that aggregate M-Score predicts lower real investment one to four quarters ahead partially accounts for why misreporting predicts recessions five to eight quarters ahead. Our findings are weaker when we use aggregate F-Score as a proxy for misreporting. Overall, this study provides novel evidence that aggregate misreporting measures can aid forecasters and regulators in predicting recessions and real GDP growth. © 2023 American Accounting Association. All rights reserved. | P21: financial misreporting; GDP; prediction; recessions | R21: Article | S21: Final | U21: Scopus | V21: 2-s2.0-85162007700
A22: Dodgson M.K.; Agoglia C.P.; Bennett G.B. | B22: Dodgson, Mary Kate (57216788494); Agoglia, Christopher P. (6506359364); Bennett, G. Bradley (56542534400) | C22: 57216788494; 6506359364; 56542534400 | D22: The Effect of Negative Expectancy Violations and Relational Familiarity on Client Managers’ Negotiation Positions | E22: 2023 | F22: Accounting Review | G22: 35 | H22: 3 | J22: 1 | K22: 24 | L22: 2 | M22: 10.2308/TAR-2017-0528 | N22: https://www.scopus.com/inward/record.uri?eid=2-s2.0-85173773203&doi=10.2308%2FTAR-2017-0528&partnerID=40&md5=39be31753550b4e122d7fa612fd199f5 | O22: During the interactive process of issue resolution, client managers may develop expectations about the auditor’s position. We examine the effect that negative expectancy violations have on managers’ pre-negotiation positions and how relational familiarity can moderate this effect. Through a series of experiments, we find that, when the partner’s proposed adjustment is within the client’s original expectations, managers offer greater concessions to a more familiar partner than to a less familiar partner. However, depending on relational familiarity, client managers react to expectancy violations very differently. Managers react more severely when a more familiar partner violates expectations, offering lower negotiation concessions than when no violation occurs. In contrast, managers tend to ignore violations committed by a less familiar partner, offering similar negotiation concessions whether or not a violation has occurred. Furthermore, we find support for a practical intervention to repair damage from expectancy violations committed by more familiar partners. © 2023 American Accounting Association. All rights reserved. | P22: auditor-client negotiation; auditor-client relationships; expectancy violations; partner tenure; relational familiarity; resolving audit differences | R22: Review | S22: Final | U22: Scopus | V22: 2-s2.0-85173773203
A23: Çetin F.M. | B23: Çetin, Furkan M. (60400357900) | C23: 60400357900 | D23: The Real Effects of Accounting on R&D Alliance Formations and Innovation: Evidence from ASC 606 | E23: 2026 | F23: Accounting Review | G23: 101 | H23: 1 | J23: 103 | K23: 135 | L23: 0 | M23: 10.2308/TAR-2022-0302 | N23: https://www.scopus.com/inward/record.uri?eid=2-s2.0-105030239500&doi=10.2308%2FTAR-2022-0302&partnerID=40&md5=d4dec97e0c7161100a4f69485bfd8797 | O23: I examine how Accounting Standards Codification (ASC) 606 affects R&D alliance formations and innovation in the drug development industry. ASC 606 alters revenue recognition timing and increases disclosure requirements. I document that firms dependent on R&D alliance revenues accelerate revenue recognition and expand revenue-related disclosures following ASC 606 adoption. These concurrent changes reduce information asymmetry, both between firms and between managers and investors, but only when increased disclosure accompanies accelerated recognition. Consistent with these net reductions in information asymmetry, affected firms raise more equity capital and increase R&D investment. Notably, these firms, which historically acted as technology providers (principals), form more R&D alliances as technology acquirers (partners). Consequently, they exhibit higher innovation output, measured by new patents and drug candidates. This study identifies a specific mechanism through which accounting standards can stimulate innovation: reduced information asymmetry that facilitates strategic R&D alliance formation. © 2026, American Accounting Association. All rights reserved. | P23: ASC 606; innovation; R&D alliances; real effects; revenue recognition | R23: Article | S23: Final | T23: All Open Access; Bronze Open Access; Green Open Access | U23: Scopus | V23: 2-s2.0-105030239500
A24: Smith K.C. | B24: Smith, Kevin C. (57194875446) | C24: 57194875446 | D24: An Option-Based Approach to Measuring Disclosure Asymmetry | E24: 2023 | F24: Accounting Review | G24: 98 | H24: 4 | J24: 373 | K24: 403 | L24: 2 | M24: 10.2308/TAR-2020-0623 | N24: https://www.scopus.com/inward/record.uri?eid=2-s2.0-85168457899&doi=10.2308%2FTAR-2020-0623&partnerID=40&md5=ffd752762f8bd222100be6e1e43ee707 | O24: In this paper, I develop a measure of the difference in the amount of information that investors expect a forthcoming disclosure to contain should it reveal good news versus bad news (the disclosure's "asymmetry"). To do so, I first show that this asymmetry is linked to the skewness of returns that the disclosure creates. I then show that this skewness can be measured using a weighted change in option-implied return skewness leading up to the disclosure's release. The measure's ability to capture investors' prior beliefs regarding asymmetry is advantageous when studying ex ante decisions including contracting and information acquisition choices. I implement it on a sample of large firms' quarterly earnings announcements, finding evidence that investors anticipate cross-sectional but not time-series variation in earnings' asymmetry. © 2023 American Accounting Association. All rights reserved. | P24: conservatism; disclosure; earnings announcements; implied volatility; model-free implied skewness; option prices; skewness; volatility surface | R24: Article | S24: Final | U24: Scopus | V24: 2-s2.0-85168457899
A25: García-Feijóo L.; Jensen T.K.; Koch P.D. | B25: García-Feijóo, Luis (9747559700); Jensen, Tyler K. (57201338065); Koch, Paul D. (7202929123) | C25: 9747559700; 57201338065; 7202929123 | D25: Operating Leverage and Stock Returns under Different Aggregate Funding Conditions | E25: 2024 | F25: Accounting Review | G25: 99 | H25: 3 | J25: 169 | K25: 199 | L25: 2 | M25: 10.2308/TAR-2022-0051 | N25: https://www.scopus.com/inward/record.uri?eid=2-s2.0-85192317995&doi=10.2308%2FTAR-2022-0051&partnerID=40&md5=07e0fd145e14c50c0a124919ef0fa019 | O25: We document time-varying interrelations between aggregate funding conditions and the impact of operating leverage (OL) on stock returns. OL represents a primitive source of risk, which helps explain the well established unconditional relation between OL and future returns. However, the outperformance of firms with high OL occurs exclusively during periods of unconstrained funding. Although high OL represents operational inflexibility, when the Fed eases funding constraints, improved capital availability mitigates this inflexibility. Consequently, investors bid up the prices of stocks with high OL when aggregate funding constraints are loosened to reflect their lower risk and greater expected performance in unconstrained periods. © 2024 American Accounting Association. All rights reserved. | P25: aggregate funding conditions; monetary policy; operating leverage; sticky input prices; time-varying risk premium | R25: Article | S25: Final | U25: Scopus | V25: 2-s2.0-85192317995
A26: Rimkus D. | B26: Rimkus, Dan (57218670104) | C26: 57218670104 | D26: Client Social Status and Cooperation with Audit Requests | E26: 2024 | F26: Accounting Review | G26: 99 | H26: 3 | J26: 429 | K26: 449 | L26: 5 | M26: 10.2308/TAR-2022-0307 | N26: https://www.scopus.com/inward/record.uri?eid=2-s2.0-85192317879&doi=10.2308%2FTAR-2022-0307&partnerID=40&md5=acb91e3145daffee40b7fa84058312b4 | O26: Auditors collect evidence from clients that vary in social status. I investigate how these status differences interact with the costliness of auditor requests, thereby influencing client cooperation during evidence collection. I develop theory predicting that higher-status clients’ cooperation decisions will be more sensitive to differences in the costliness of requests than lower-status clients’ decisions. I test this theory across two experiments using multiple methods, leveraging the complementary strengths of each method. Experiment 1 is a more abstract experiment in the tradition of experimental economics, and Experiment 2 is a more contextualized experiment using participants with prior experience interacting with auditors. Results from both experiments support the theorized interaction between the costliness of audit requests and client social status. This conclusion carries implications for practitioners in assessing strategic tactics that will efficiently and effectively increase client cooperation. © 2024 American Accounting Association. All rights reserved. | P26: audit evidence; auditor-client interaction; client cooperation; status | R26: Article | S26: Final | U26: Scopus | V26: 2-s2.0-85192317879
A27: Edwards A.; Kubata A.; Shevlin T. | B27: Edwards, Alexander (55419774200); Kubata, Adrian (56192431800); Shevlin, Terry (6601990549) | C27: 55419774200; 56192431800; 6601990549 | D27: The decreasing trend in U.S. cash effective tax rates: The role of growth in pre-tax income | E27: 2021 | F27: Accounting Review | G27: 96 | H27: 5 | J27: 231 | K27: 261 | L27: 28 | M27: 10.2308/TAR-2019-0252 | N27: https://www.scopus.com/inward/record.uri?eid=2-s2.0-85107132059&doi=10.2308%2FTAR-2019-0252&partnerID=40&md5=83c99e91a277908f96691a80c42037d9 | O27: We develop a linear corporate tax function where taxes paid are regressed on pre-tax income and an intercept. We show that if the intercept is positive, cash ETRs are a convex function of pre-tax income. We present large-sample evidence consistent with this ETR convexity. Thus, although firms may have stable linear tax functions (i.e., constant parameters in the linear tax model) representing stable tax avoidance behavior, ETRs can change over time because of growth in pre-tax income. Consequently, simply examining changes (or differences) in cash ETRs is nondiagnostic about whether tax avoidance has changed over time (or differs across firms). We illustrate our argument by showing that all of the observed downward trend in cash ETRs documented by Dyreng et al. (2017) can be explained by growth in pre-tax income. The wholesale concern about increased tax avoidance over time might be overstated. © 2021 American Accounting Association. All rights reserved. | P27: Cash effective tax rate; Corporate tax function; Time trend | R27: Article | S27: Final | U27: Scopus | V27: 2-s2.0-85107132059
A28: Ahn B.H.; Bushman R.M.; Patatoukas P.N. | B28: Ahn, Byung Hyun (59207132100); Bushman, Robert M. (6603387885); Patatoukas, Panos N. (53985113200) | C28: 59207132100; 6603387885; 53985113200 | D28: Under the Hood of Activist Fraud Campaigns: Private Information Quality, Disclosure Incentives, and Stock Lending Dynamics | E28: 2024 | F28: Accounting Review | G28: 99 | H28: 6 | J28: 1 | K28: 26 | L28: 4 | M28: 10.2308/TAR-2023-0392 | N28: https://www.scopus.com/inward/record.uri?eid=2-s2.0-85208678081&doi=10.2308%2FTAR-2023-0392&partnerID=40&md5=4cd2ab76414c814629d59abb68bb8289 | O28: Although activist short sellers can play a crucial role in fraud detection, they have come under scrutiny following accusations of systematically disseminating false negative information. We develop a framework delineating the roles of campaign-specific private information quality and short-selling dynamics in shaping disclosure incentives. We predict that the act of disclosure combined with pre-disclosure stock lending dynamics is informative about the quality of an activist's private information. We find that increased pre-disclosure shorting intensity is associated with more negative post-disclosure returns, adverse media coverage, and consequential campaign outcomes, including auditor turnover, accounting restatements, class-action lawsuits, and performancerelated delistings. Furthermore, elevated short-selling costs and risks magnify the association between predisclosure shorting intensity and post-disclosure underperformance. Finally, we examine V-shaped reversals and short covering following activists' disclosures and find no evidence of systematic manipulation. We conclude that activists disclosing fraud allegations under their own names are discouraged from engaging in "short-and-distort" schemes. © 2024 American Accounting Association. All rights reserved. | P28: activist short sellers; disclosure; fraud detection; stock lending market | R28: Article | S28: Final | U28: Scopus | V28: 2-s2.0-85208678081
A29: Basu S.; Kaviani M.S.; Maleki H. | B29: Basu, Sudipta (7403656354); Kaviani, Mahsa S. (57218330457); Maleki, Hosein (57218326685) | C29: 7403656354; 57218330457; 57218326685 | D29: Bank Entry Barriers and Firms’ Risk-Taking | E29: 2025 | F29: Accounting Review | G29: 100 | H29: 1 | J29: 55 | K29: 85 | L29: 2 | M29: 10.2308/TAR-2021-0604 | N29: https://www.scopus.com/inward/record.uri?eid=2-s2.0-85214894736&doi=10.2308%2FTAR-2021-0604&partnerID=40&md5=d94a89a0bb683948dfda7475833bdda3 | O29: We study how nonfinancial firms’ operating risks change after bank competition increases. By exploiting the 1990s staggered regulatory reforms across U.S. states that allowed interstate banking and branching, we show that out-of-state bank entry was associated with lower borrower risk-taking on average. Large, profitable, safe, and geographically diversified firms signed up as new clients of large entrant banks, which offered larger and cheaper loans that reflected their higher efficiency and risk reduction through geographical diversification. We argue that these large banks could substitute for local relationship lending with more data collection from branches in multiple states. Firms that began borrowing from entrant banks increased capital expenditures and project-specific financing and kept R&D expenses stable but reduced R&D risk. Firms that continued borrowing from incumbent banks paid higher interest rates and increased their risk, suggesting that their credit access fell. States that opened up more had bigger changes in these outcomes. © 2025 American Accounting Association. All rights reserved. | P29: assortative matching; bank competition; barriers to entry; corporate risk-taking; operational risk | R29: Article | S29: Final | T29: All Open Access; Bronze Open Access | U29: Scopus | V29: 2-s2.0-85214894736
A30: Hecht G.; Maas V.S.; van Rinsum M. | B30: Hecht, Gary (7006773315); Maas, Victor S. (24537627400); van Rinsum, Marcel (55255149300) | C30: 7006773315; 24537627400; 55255149300 | D30: The Effects of Transparency and Group Incentives on Managers’ Strategic Promotion Behavior | E30: 2023 | F30: Accounting Review | G30: 98 | H30: 7 | J30: 239 | K30: 260 | L30: 7 | M30: 10.2308/TAR-2020-0208 | N30: https://www.scopus.com/inward/record.uri?eid=2-s2.0-85176396002&doi=10.2308%2FTAR-2020-0208&partnerID=40&md5=eee1a60c3ebc4c909193a45f47535685 | O30: We investigate managers’ propensity to engage in strategic promotion behavior. Strategic promotion behavior occurs when managers pursue personal economic interests when contributing to employee promotion decisions, such that the probability that relatively lower performing employees are selected for a promotion is increased. We develop theory about how two important organizational characteristics—transparency about individual performance levels and the presence of group incentives—jointly affect managers’ tendency to strategically influence promotion decisions. Using a stylized lab experiment, we find that transparency about individual performance levels decreases strategic promotion behavior when group incentives are absent but not when group incentives are present. We discuss how our findings contribute to our understanding of management accounting and control systems. © 2023 American Accounting Association. All rights reserved. | P30: discretion; experiment; fairness; incentives; performance evaluation; promotions; strategic behavior; teams; transparency | R30: Article | S30: Final | U30: Scopus | V30: 2-s2.0-85176396002
A31: Manthei K.; Sliwka D.; Vogelsang T. | B31: Manthei, Kathrin (55937566900); Sliwka, Dirk (6603137505); Vogelsang, Timo (57226102017) | C31: 55937566900; 6603137505; 57226102017 | D31: Information, Incentives, and Attention: A Field Experiment on the Interaction of Management Controls | E31: 2023 | F31: Accounting Review | G31: 98 | H31: 5 | J31: 455 | K31: 479 | L31: 13 | M31: 10.2308/TAR-2019-1065 | N31: https://www.scopus.com/inward/record.uri?eid=2-s2.0-85169790083&doi=10.2308%2FTAR-2019-1065&partnerID=40&md5=1bb478fe15e551f6fc3e0c07e2234c0a | O31: We study the profit effects and interplay of two core accounting practices in a field experiment in a large retail chain. In a 2 × 2 factorial design, we vary (1) whether store managers obtain decision-facilitating information on a profit metric and (2) whether they receive performance pay based on the same metric.We find that both practices increase profits significantly. In contrast to reasoning based on standard economic theory, we do not find complementarity between both interventions. Rather, we detect evidence in line with an attention-directing role of both practices: the introduction of each raises attention to the underlying objective, which induces a countervailing substitution effect. © 2023 American Accounting Association. All rights reserved. | P31: attention direction; complementarity; decision facilitating; decision influencing; field experiment; interdependency; management controls; performance pay | R31: Article | S31: Final | U31: Scopus | V31: 2-s2.0-85169790083
A32: Petrov E.; Stocken P.C. | B32: Petrov, Evgeny (57219669119); Stocken, Phillip C. (6603184010) | C32: 57219669119; 6603184010 | D32: Auditor Specialization and Information Spillovers | E32: 2022 | F32: Accounting Review | G32: 97 | H32: 7 | J32: 401 | K32: 428 | L32: 17 | M32: 10.2308/TAR-2020-0423 | N32: https://www.scopus.com/inward/record.uri?eid=2-s2.0-85130448465&doi=10.2308%2FTAR-2020-0423&partnerID=40&md5=e177796e7b26319bc22f5e932788e146 | O32: We study the determinants of auditor industry specialization, the impact of specialization on fees and audit quality, and a regulator's optimal choice of audit standards in the presence of specialization. In industries with correlated firm values, a specialist auditor enjoys synergies from information spillovers between clients. These spillovers, however, only induce a specialist to decrease audit effort when the cost of effort and the prior precision of the firms' values are low. We derive empirical predictions about the determinants of specialization, and show that specialization benefits firms through lower expected fees and higher audit reporting quality, but only enhances the usefulness of reports to investors when the specialist exerts high audit effort. In a regulated setting, a stricter audit standard affects fees through its impact on specialization. We provide conditions under which standards that maximize firm value will be more strict and less strict when a regulator recognizes synergies. © 2022 American Accounting Association. All rights reserved. | P32: audit fees; audit quality; auditor specialization; information spillovers; PCAOB regulation | R32: Article | S32: Final | U32: Scopus | V32: 2-s2.0-85130448465
A33: Hammersley J.S.; Ricci M.A. | B33: Hammersley, Jacqueline S. (13003935400); Ricci, Michael A. (57215932328) | C33: 13003935400; 57215932328 | D33: Using Audit Programs to Improve Auditor Evidence Collection | E33: 2021 | F33: Accounting Review | G33: 96 | H33: 1 | J33: 251 | K33: 272 | L33: 12 | M33: 10.2308/TAR-2018-0120 | N33: https://www.scopus.com/inward/record.uri?eid=2-s2.0-85101258851&doi=10.2308%2FTAR-2018-0120&partnerID=40&md5=e175d5a9e0cb90f7a7040ede4e0bffc8 | O33: Auditors experience difficulty auditing accounts for which it is difficult to identify in advance all the evidence necessary to perform an effective audit. These accounts are challenging because they commonly require auditors to collect additional, relevant evidence in response to new information received during evidence collection. We address this experimentally by examining whether changing the focus of audit programs from plan-focused (i.e., focused on the planned audit procedures) to goal-focused (i.e., focused on the task goal) improves auditors’ collection of relevant evidence that is not identifiable at audit program creation. We expect goal-focused auditors to remain open to more ways to achieve their goal. Consequently, we expect and find that goal-focused auditors collect more effective evidence than plan-focused auditors and follow up more effectively on this evidence. This suggests that a goal-focused approach improves audit quality on tasks requiring auditors to flexibly respond to new information. © 2021 American Accounting Association. All rights reserved. | P33: Audit planning; Audit programs; Evidence collection; Goals | R33: Article | S33: Final | U33: Scopus | V33: 2-s2.0-85101258851
A34: Hilary G.; Tian X.; Yu M. | B34: Hilary, Gilles (6505892271); Tian, Xiaoli (58345641900); Yu, Miaomiao (59940016300) | C34: 6505892271; 58345641900; 59940016300 | D34: Does Meeting Financial Expectations Boost Employee Satisfaction? | E34: 2025 | F34: Accounting Review | G34: 100 | H34: 4 | J34: 277 | K34: 302 | L34: 2 | M34: 10.2308/TAR-2022-0018 | N34: https://www.scopus.com/inward/record.uri?eid=2-s2.0-105009642006&doi=10.2308%2FTAR-2022-0018&partnerID=40&md5=3d3d3a4b12c801f8f43499296040b32d | O34: We investigate whether meeting Wall Street’s expectations affects rank-and-file employees’ satisfaction. Controlling for firms’ underlying financial performance, we find that those currently working for firms that meet or marginally beat analysts’ forecasts experience increased job satisfaction. This positive effect is concentrated among employees who are less transient, receive more nonexecutive stock options, or are more unionized. Furthermore, the positive effect exists only when employees do not incur higher costs associated with reaching the threshold because they overwork, suffer from labor law violations, or experience layoffs. Lastly, more senior or highly skilled employees respond more strongly when their employer meets Wall Street’s expectations. These results suggest that the effect of meeting earnings targets on employee satisfaction is significant when employees’ incentives align more with those of their employer or when employees are not unduly pressured. © 2025 American Accounting Association. All rights reserved. | P34: earnings targets; employee satisfaction; Glassdoor | R34: Article | S34: Final | T34: All Open Access; Bronze Open Access | U34: Scopus | V34: 2-s2.0-105009642006
A35: Christensen B.E.; Cline B.N.; Lundstrom N.G.; Yore A.S. | B35: Christensen, Brant E. (54987433400); Cline, Brandon N. (36598104200); Lundstrom, Nathan G. (57220897729); Yore, Adam S. (56003709500) | C35: 54987433400; 36598104200; 57220897729; 56003709500 | D35: Do Auditors View Off-the-Clock Misbehavior by Company Leadership as a Signal of Tone at the Top? | E35: 2024 | F35: Accounting Review | G35: 99 | H35: 5 | J35: 171 | K35: 196 | L35: 1 | M35: 10.2308/TAR-2021-0026 | N35: https://www.scopus.com/inward/record.uri?eid=2-s2.0-85203412911&doi=10.2308%2FTAR-2021-0026&partnerID=40&md5=177573021ba3860c9fa2310154b39c55 | O35: We study off-the-clock indiscretion accusations against corporate officers and directors and examine the extent, effectiveness, and context of auditors’ response. In the year that indiscretion allegations are first publicized, auditors charge higher fees and are more likely to resign. Auditors respond to allegations against both top executives and board members. Further, reactions are strongest when allegations demonstrate a lack of individual integrity and, separately, when the audit office has previously audited other similarly accused clients. Importantly, the resulting increase in auditors’ effort partially negates the association between indiscretions and lower financial reporting quality. However, auditors are primarily reactive, rather than proactive, and their response is stronger when the accused client is less important economically. These results suggest that company leadership’s off-the-clock indiscretions are signals to auditors of poor tone at the top, but the audit response is not uniform across all clients. © 2024 American Accounting Association. All rights reserved. | P35: auditor; indiscretions; integrity; risk; tone at the top | R35: Article | S35: Final | T35: All Open Access; Bronze Open Access | U35: Scopus | V35: 2-s2.0-85203412911
